Traceback (most recent call last):
  File "app_main.py", line 75, in run_toplevel
  File "/home/ubuntu/FrameworkBenchmarks/installs/pypy/bin/gunicorn", line 9, in <module>
    load_entry_point('gunicorn==18.0', 'console_scripts', 'gunicorn')()
  File "/home/ubuntu/FrameworkBenchmarks/installs/pypy/site-packages/gunicorn/app/wsgiapp.py", line 71, in run
    WSGIApplication("%(prog)s [OPTIONS] [APP_MODULE]").run()
  File "/home/ubuntu/FrameworkBenchmarks/installs/pypy/site-packages/gunicorn/app/base.py", line 143, in run
    Arbiter(self).run()
  File "/home/ubuntu/FrameworkBenchmarks/installs/pypy/site-packages/gunicorn/arbiter.py", line 175, in run
    self.manage_workers()
  File "/home/ubuntu/FrameworkBenchmarks/installs/pypy/site-packages/gunicorn/arbiter.py", line 470, in manage_workers
    self.spawn_workers()
  File "/home/ubuntu/FrameworkBenchmarks/installs/pypy/site-packages/gunicorn/arbiter.py", line 529, in spawn_workers
    self.spawn_worker()
  File "/home/ubuntu/FrameworkBenchmarks/installs/pypy/site-packages/gunicorn/arbiter.py", line 508, in spawn_worker
    traceback.format_exc())
  File "/home/ubuntu/FrameworkBenchmarks/installs/pypy/lib-python/2.7/traceback.py", line 241, in format_exc
    return ''.join(format_exception(etype, value, tb, limit))
  File "/home/ubuntu/FrameworkBenchmarks/installs/pypy/lib-python/2.7/traceback.py", line 141, in format_exception
    list = list + format_tb(tb, limit)
  File "/home/ubuntu/FrameworkBenchmarks/installs/pypy/lib-python/2.7/traceback.py", line 76, in format_tb
    return format_list(extract_tb(tb, limit))
  File "/home/ubuntu/FrameworkBenchmarks/installs/pypy/lib-python/2.7/traceback.py", line 101, in extract_tb
    line = linecache.getline(filename, lineno, f.f_globals)
  File "/home/ubuntu/FrameworkBenchmarks/installs/pypy/lib-python/2.7/linecache.py", line 14, in getline
    lines = getlines(filename, module_globals)
  File "/home/ubuntu/FrameworkBenchmarks/installs/pypy/lib-python/2.7/linecache.py", line 40, in getlines
    return updatecache(filename, module_globals)
  File "/home/ubuntu/FrameworkBenchmarks/installs/pypy/lib-python/2.7/linecache.py", line 127, in updatecache
    with open(fullname, 'rU') as fp:
  File "/home/ubuntu/FrameworkBenchmarks/installs/pypy/site-packages/gunicorn/workers/gtornado.py", line 35, in handle_quit
    self.ioloop.stop()
AttributeError: 'TornadoWorker' object has no attribute 'ioloop'
Traceback (most recent call last):
  File "app_main.py", line 75, in run_toplevel
  File "/home/ubuntu/FrameworkBenchmarks/installs/pypy/bin/gunicorn", line 9, in <module>
    load_entry_point('gunicorn==18.0', 'console_scripts', 'gunicorn')()
  File "/home/ubuntu/FrameworkBenchmarks/installs/pypy/site-packages/gunicorn/app/wsgiapp.py", line 71, in run
    WSGIApplication("%(prog)s [OPTIONS] [APP_MODULE]").run()
  File "/home/ubuntu/FrameworkBenchmarks/installs/pypy/site-packages/gunicorn/app/base.py", line 143, in run
    Arbiter(self).run()
  File "/home/ubuntu/FrameworkBenchmarks/installs/pypy/site-packages/gunicorn/arbiter.py", line 203, in run
    self.halt(reason=inst.reason, exit_status=inst.exit_status)
  File "/home/ubuntu/FrameworkBenchmarks/installs/pypy/site-packages/gunicorn/arbiter.py", line 298, in halt
    self.stop()
  File "/home/ubuntu/FrameworkBenchmarks/installs/pypy/site-packages/gunicorn/arbiter.py", line 341, in stop
    self.reap_workers()
  File "/home/ubuntu/FrameworkBenchmarks/installs/pypy/site-packages/gunicorn/arbiter.py", line 452, in reap_workers
    raise HaltServer(reason, self.WORKER_BOOT_ERROR)
HaltServer: <HaltServer 'Worker failed to boot.' 3>
curl: (7) Failed to connect to 127.0.0.1 port 8080: Connection refused
curl: (7) Failed to connect to 127.0.0.1 port 8080: Connection refused
